Workbook

Sheet 12-Month Calendar
A1: 12-Month Fundraising Calendar (Nov 2026 - Oct 2027)
A2: Goal $ adds up the Master Action Table for each month. Dates checked Oct 13, 2026; '~' = estimate.
A5: Month | B5: Theme | C5: Key dates | D5: Campaigns | E5: Grants / funders | F5: Donor care | G5: Goal $ (from actions)
A6: Nov 2026 | B6: Get ready + first asks | C6: Nov 2 NTxGD reg. opens; Nov 8 Diwali; Nov 26 Thanksgiving; Nov 30 Walmart deadline | D6: Maa's Circle launch; Share a Plate | E6: Walmart; CFT profile | F6: Set up CRM; 48-hr thank-yous start | G6: =SUMIF('Master Action Table'!$A:$A,A6,'Master Action Table'!$D:$D)
A7: Dec 2026 | B7: Year-end giving | C7: Dec 1 Giving Tuesday; Dec 31 tax year ends | D7: Giving Tuesday; year-end appeal | E7: Kroger; Albertsons | F7: Holiday cards to top 50 donors | G7: =SUMIF('Master Action Table'!$A:$A,A7,'Master Action Table'!$D:$D)
A8: Jan 2027 | B8: Thank + build | C8: Jan 29 year-end statements | D8: Founding Friends (Maa's Place) | E8: NTFB (Jan review); Moody; Meadows | F8: Thank-a-thon calls | G8: =SUMIF('Master Action Table'!$A:$A,A8,'Master Action Table'!$D:$D)
A9: Feb 2027 | B9: Ramadan season | C9: ~Feb 8 Ramadan begins; Feb 15 Hoblitzelle window opens | D9: Share a Meal (faith partners); sponsor tiers | E9: Walmart cycle 1 (if repeated) | F9: Impact update #1 | G9: =SUMIF('Master Action Table'!$A:$A,A9,'Master Action Table'!$D:$D)
A10: Mar 2027 | B10: Maa's Place opens [TBA] | C10: ~Mar 9-10 Eid al-Fitr; Chipotle reopens | D10: Opening event; Founding Friends close | E10: Carrollton CDBG (if open); H-E-B | F10: Tour invites for $250+ donors | G10: =SUMIF('Master Action Table'!$A:$A,A10,'Master Action Table'!$D:$D)
A11: Apr 2027 | B11: Dinner prep | C11: Apr 19 Maa's Day campaign starts | D11: Dinner sponsors + tickets | E11: Kroger quarterly | F11: Volunteer appreciation | G11: =SUMIF('Master Action Table'!$A:$A,A11,'Master Action Table'!$D:$D)
A12: May 2027 | B12: Maa's Day | C12: May 9 Mother's Day | D12: Maa's Day tributes; Community Dinner | E12: - | F12: Dinner thank-yous in 48 hrs | G12: =SUMIF('Master Action Table'!$A:$A,A12,'Master Action Table'!$D:$D)
A13: Jun 2027 | B13: Mid-year | C13: Hoblitzelle 2nd window Jun 15 | D13: Birthday fundraisers | E13: Dallas Foundation summer (if open) | F13: Mid-year impact update | G13: =SUMIF('Master Action Table'!$A:$A,A13,'Master Action Table'!$D:$D)
A14: Jul 2027 | B14: Summer needs | C14: - | D14: Summer senior meals appeal | E14: Sprouts (if open) | F14: Monthly donor upgrade ask | G14: =SUMIF('Master Action Table'!$A:$A,A14,'Master Action Table'!$D:$D)
A15: Aug 2027 | B15: Giving Day build | C15: ~Late Aug NTxGD early giving | D15: Peer-to-peer pages; match pool | E15: Rees-Jones LOI (BSV, if dated) | F15: Lapsed donor win-back | G15: =SUMIF('Master Action Table'!$A:$A,A15,'Master Action Table'!$D:$D)
A16: Sep 2027 | B16: North Texas Giving Day | C16: Sep 16 NTxGD | D16: NTxGD push | E16: - | F16: Thank all NTxGD donors in 48 hrs | G16: =SUMIF('Master Action Table'!$A:$A,A16,'Master Action Table'!$D:$D)
A17: Oct 2027 | B17: Review + plan year 2 | C17: Diwali 2027 (date TBC) | D17: Annual impact report | E17: Renewals list | F17: Donor survey | G17: =SUMIF('Master Action Table'!$A:$A,A17,'Master Action Table'!$D:$D)
A18: Total | G18: =SUM(G6:G17)

Sheet Master Action Table
A1: Master Action Table
A2: Goal $ = planning estimate. Status dropdown. Nothing is sent or submitted without Aslam's approval.
A5: Month | B5: Activity | C5: Owner | D5: Goal $ | E5: Status | F5: Due / notes | G5: Actual $
A6: Nov 2026 | B6: Fix donate page: real monthly links, custom amount link, program tags on Meals/BSV pages, IRS receipt text | C6: Assistant (draft) / Aslam (approve) | D6: 0 | E6: Not started
A7: Nov 2026 | B7: Request Stripe nonprofit rate (2.2% + 30c) | C7: Aslam | D7: 0 | E7: Not started
A8: Nov 2026 | B8: Set up donor database (Little Green Light) and import Stripe + check/cash records | C8: Assistant / Staff | D8: 0 | E8: Not started
A9: Nov 2026 | B9: Launch Maa's Circle monthly giving (goal: 40 monthly donors by Dec 31) | C9: Aslam / Assistant | D9: 1500 | E9: Not started
A10: Nov 2026 | B10: Walmart Spark Good applications to 2-3 nearby stores (deadline Nov 30) | C10: Assistant (draft) / Aslam (submit) | D10: 5000 | E10: Not started
A11: Nov 2026 | B11: Register for North Texas Giving Day 2027 (opens Nov 2) | C11: Assistant / Aslam | D11: 0 | E11: Not started
A12: Nov 2026 | B12: Complete CFT Nonprofit Gateway Profile | C12: Assistant (draft) / Aslam | D12: 0 | E12: Not started
A13: Nov 2026 | B13: Diwali (Nov 8) + Thanksgiving (Nov 26) 'Share a Plate' with partner temples/businesses | C13: Aslam / Volunteer | D13: 6000 | E13: Not started
A14: Nov 2026 | B14: Recruit 3 board/fundraising committee members | C14: Aslam | D14: 0 | E14: Not started
A15: Dec 2026 | B15: Giving Tuesday Dec 1 (match from 1-2 sponsors) | C15: Aslam / Assistant | D15: 8000 | E15: Not started
A16: Dec 2026 | B16: Year-end appeal: letter + 4 emails (Dec 1, 15, 29, 31) | C16: Assistant (draft) / Aslam | D16: 12000 | E16: Not started
A17: Dec 2026 | B17: Kroger + Albertsons/Nourishing Neighbors requests | C17: Assistant (draft) / Aslam | D17: 3000 | E17: Not started
... A47: Oct 2027 | B47: Restaurant give-back night #6 | C47: Volunteer | D47: 800 | E47: Not started
A48: Total | D48: =SUM(D6:D47) | G48: =SUM(G6:G47)
A49: Done | D49: =COUNTIF(E6:E47,"Done")&" of "&COUNTA(B6:B47)

Sheet Funders
A1: Funders and Programs (checked Oct 13, 2026)
A2: Verified = program, eligibility and link confirmed on an official page. 'Unverified' text inside a cell means that detail is not confirmed. Do not contact anyone without Aslam's approval.
A4: Verified: | B4: =COUNTIF(I7:I36,"Verified") | C4: Unverified: | D4: =COUNTIF(I7:I36,"Unverified") | F4: Facts verified: | G4: =COUNTIF(I41:I72,"Verified") | H4: Facts unverified: | I4: =COUNTIF(I41:I72,"Unverified")
A6: # | B6: Funder / program | C6: Category | D6: Fits | E6: What they fund | F6: Typical size | G6: Timing / deadline | H6: Link | I6: Verified? | J6: Watch-outs / eligibility | K6: Next step | L6: Owner | M6: Pipeline status | N6: Last checked | O6: Notes
A7: 1 | B7: North Texas Giving Day 2027 (Communities Foundation of Texas) | C7: Giving day | D7: All | E7: Online giving day for nonprofits serving 20 North Texas counties; CFT covers card fees | F7: Depends on our donors + any match pools; est. $5k-$20k | G7: Registration opens Nov 2, 2026; Giving Day Thu Sep 16, 2027 (early giving ~late Aug) | H7: https://www.northtexasgivingday.org/p/registration | I7: Verified | J7: 2027 registration rules/fees not yet posted | K7: Register in Nov 2026; recruit a match sponsor by Jul 2027 | L7: Assistant (prep) / Aslam (submit) | M7: Researching | N7: Oct 13, 2026
A8: 2 | B8: Communities Foundation of Texas - Nonprofit Gateway Profile | C8: Community foundation | D8: All | E8: Grants are now nearly all invitation-only; profile puts us on CFT's radar (also DAF holders) | F8: Unverified (third-party listings say $5k-$50k) | G8: Rolling profile; no open application | H8: https://www.cftexas.org/nonprofits/grants/ | I8: Verified | J8: Needs 501(c)(3) active 2+ yrs; 50%+ served in eligible counties | K8: Complete Gateway Profile in Nov 2026 | L8: Assistant (draft) / Aslam | M8: Researching | N8: Oct 13, 2026
A9: 3 | B9: The Dallas Foundation - Summer Grants Cycle (Family Economic Stability & Critical Needs) | C9: Community foundation | D9: Meals, Maa's Place | E9: Essential services for children, families, older adults in Dallas County; general operating OK | F9: $5,000-$75,000 (2026 cycle) | G9: 2026 window was Jun 10-26 (closed). 2027 dates not posted - expect ~June 2027 (Unverified) | H9: https://www.dallasfoundation.org/our-impact/grant-opportunities/ | I9: Verified | J9: Over 50% of clients must live in Dallas County; asks for 990, budget, audited financials if available; no event underwriting | K9: Confirm county mix; watch page from Apr 2027 | L9: Assistant | M9: Researching | N9: Oct 13, 2026
A10: 4 | B10: The Dallas Foundation - Spring cycle (Specialized Health & Disability) | C10: Community foundation | D10: BSV (later) | E10: 2026 spring focus incl. specialized health & disability programs | F10: Unverified | G10: 2026 window was Jan 14-28; 2027 not posted | H10: https://www.dallasfoundation.org/our-impact/grant-opportunities/ | I10: Verified | J10: 2026 spring cycle required org budget over $500,000; BSV not open yet | K10: Revisit after BSV opens | L10: Assistant | M10: Researching | N10: Oct 13, 2026
A11: 5 | B11: The Meadows Foundation - Human Services | C11: Private foundation | D11: Meals, Maa's Place | E11: Programs that improve quality of life for vulnerable Texans; up to 50% of giving in DFW | F11: Unverified | G11: Rolling; submit 4-5 months before funds are needed; monthly info sessions | H11: https://www.mfi.org/how-to-apply/ | I11: Verified | J11: Wants measurable outcomes and other funding secured | K11: Attend an info session; call program officer (Aslam's decision) | L11: Aslam / Assistant | M11: Researching | N11: Oct 13, 2026
A12: 6 | B12: The Rees-Jones Foundation | C12: Private foundation | D12: BSV (children & families) | E12: DFW children, youth and their families (and companion animals) within defined portfolios | F12: Unverified | G12: Rolling Letter of Inquiry; ~30 days to invite/decline; ~4 months staff review | H12: https://www.rees-jonesfoundation.org/apply-for-funding/ | I12: Verified | J12: Must match a portfolio; BSV must be operating | K12: Check portfolio fit; LOI after BSV opening date is set | L12: Assistant | M12: Researching | N12: Oct 13, 2026
A13: 7 | B13: The Moody Foundation - General Grant Inquiry | C13: Private foundation | D13: All | E13: Texas: education, social services & family well-being, health & wellness, arts | F13: Unverified | G13: Rolling inquiry; up to ~6 months to decision; 4 trustee meetings/yr | H13: https://moodyf.org/application-process/ | I13: Verified | J13: One active inquiry per organization | K13: Submit one inquiry (Maa's Place opening) in Jan 2027 | L13: Assistant (draft) / Aslam | M13: Researching | N13: Oct 13, 2026
A14: 8 | B14: Hoblitzelle Foundation | C14: Private foundation | D14: Maa's Place / BSV capital | E14: Capital only: buildings, renovation, equipment, vehicles, technology (Dallas area priority) | F14: Unverified | G14: Windows Feb 15-Apr 15, 2027 and Jun 15-Aug 15, 2027 | H14: https://hoblitzelle.org/how-to-apply | I14: Verified | J14: Requires annual budget over $250,000 AND external audit within 2 years - likely NOT eligible yet | K14: Ask Aslam: budget size and audit status | L14: Aslam | M14: Researching | N14: Oct 13, 2026
A15: 9 | B15: Crystal Charity Ball | C15: Charity / foundation | D15: BSV (future) | E15: Dallas County children's charities; large multi-year project grants | F15: Unverified | G15: 2027 cycle closed Oct 8, 2026; next cycle ~Aug-Oct 2027 | H15: https://crystalcharity.org/apply-for-funding/ | I15: Verified | J15: Must have served Dallas County children 3+ years - BSV not eligible until ~3 yrs after opening | K15: Long-term only | L15: Assistant (track) | M15: Researching | N15: Oct 13, 2026
A16: 10 | B16: Walmart Spark Good Local Grants | C16: Corporate | D16: Meals | E16: Local store/Sam's Club/DC grants; hunger relief is a frequent area of support | F16: $250-$5,000 | G16: FY27 Cycle 3: Aug 1-Nov 30, 2026 (open now). Cycles 1-2 were Feb 1-Apr 15, May 1-Jul 15 | H16: https://walmart.org/how-we-give/program-guidelines/spark-good-local-grants-guidelines | I16: Verified | J16: Needs Spark Good account + Deed verification; one award per facility per fiscal year | K16: Apply to 2-3 Carrollton-area stores by Nov 30, 2026 | L16: Assistant (draft) / Aslam (submit) | M16: Researching | N16: Oct 13, 2026
A17: 11 | B17: Kroger Zero Hunger | Zero Waste Foundation + Kroger store giving | C17: Corporate | D17: Meals | E17: Hunger relief, mobile pantries, food access; stores also give cash/gift cards/product | F17: Unverified | G17: Applications reviewed quarterly (exact 2026-27 dates Unverified) | H17: https://zerohungerzerowastefoundation.org/how_we_give.html | I17: Verified | J17: Kroger Dallas Division store requests go through the Kroger proposal portal (thekrogerco.versaic.com) | K17: Submit one request in Dec 2026 | L17: Assistant (draft) / Aslam | M17: Researching | N17: Oct 13, 2026
A18: 12 | B18: Albertsons Companies Foundation / Nourishing Neighbors (Tom Thumb, Albertsons) | C18: Corporate | D18: Meals | E18: Hunger relief; Innovation Incubation Fund for new food-security ideas | F18: Unverified | G18: Rolling; reviewed monthly (per Nourishing Neighbors RFP page) | H18: https://www.nourishingneighbors.com/ | I18: Verified | J18: Must serve communities with an Albertsons-family store (Tom Thumb is in DFW); a local Tom Thumb in-kind/gift-card process is Unverified | K18: Check current open RFP; ask local Tom Thumb manager about product donations | L18: Assistant / Volunteer | M18: Researching | N18: Oct 13, 2026
... A36: 30 | B36: United Way of Denton County - Community Impact Grants | C36: United Way | D36: Low fit | E36: Youth, workforce, veterans, homelessness, behavioral health | F36: Unverified | G36: Unverified | H36: https://www.unitedwaydenton.org/community-impact-grants | I36: Verified | J36: Focus areas do not match hunger/seniors well | K36: Low priority | L36: Assistant (track) | M36: Researching | N36: Oct 13, 2026
A39: Fact-check log (rules, dates, prices)
A40: # | B40: Item | C40: Finding | E40: Finding | H40: Source | I40: Status
A41: 1 | B41: North Texas Giving Day 2026 date | E41: Thu Sep 17, 2026 (already passed) | H41: https://www.northtexasgivingday.org/p/AboutUs | I41: Verified
A42: 2 | B42: North Texas Giving Day 2027 date | E42: Thu Sep 16, 2027 | H42: https://www.cftexas.org/about-cft/blog-and-newsroom/north-texas-giving-day-2026/ | I42: Verified
A43: 3 | B43: NTxGD 2027 registration | E43: Opens Nov 2, 2026 | H43: https://www.northtexasgivingday.org/p/registration | I43: Verified
A44: 4 | B44: Giving Tuesday 2026 | E44: Tue Dec 1, 2026 (day after Thanksgiving week; Thanksgiving Nov 26) | H44: Calendar | I44: Verified
A45: 5 | B45: Diwali 2026 | E45: Sun Nov 8, 2026 | H45: https://globalpanchang.com/diwali | I45: Verified
A46: 6 | B46: Ramadan 2027 | E46: Expected to start ~Mon Feb 8, 2027; Eid al-Fitr ~Mar 9-10 (moon-sighting) | H46: https://www.khaleejtimes.com/uae/ramadan-eid-al-fitr-eid-al-adha-2027-likely-dates | I46: Unverified
A47: 7 | B47: Mother's Day 2027 | E47: Sun May 9, 2027 | H47: Calendar | I47: Verified
A48: 8 | B48: Texas raffles: who can hold them | E48: 501(c) nonprofit in existence 3+ years (plus religious societies 10+ yrs, volunteer fire/EMS) | H48: https://www.texasattorneygeneral.gov/divisions/charitable-trusts/charitable-raffles-and-casinopoker-nights | I48: Verified
A49: 9 | B49: Texas raffles: how many | E49: Up to 4 per calendar year (changed from 2 in June 2021 by HB 2757) | H49: https://www.texasattorneygeneral.gov/divisions/charitable-trusts/charitable-raffles-and-casinopoker-nights | I49: Verified
A50: 10 | B50: Texas raffles: prizes | E50: No cash prizes; purchased prize max $75,000; donated prizes no limit; must own prize or post bond | H50: https://statutes.capitol.texas.gov/Docs/OC/htm/OC.2002.htm | I50: Verified
A51: 11 | B51: Texas raffles: selling | E51: No statewide promotion or ticket sales (generally read to include the internet); no paid organizers; 5 items on each ticket | H51: https://www.texasattorneygeneral.gov/divisions/charitable-trusts/charitable-raffles-and-casinopoker-nights | I51: Verified
A52: 12 | B52: Casino/poker night fundraisers | E52: Not allowed for nonprofits in Texas | H52: https://www.texasattorneygeneral.gov/divisions/charitable-trusts/charitable-raffles-and-casinopoker-nights | I52: Verified
... A72: 32 | B72: Diwali 2027 | E72: Late Oct / early Nov 2027 - date not checked | H72: - | I72: Unverified

Sheet Budget
A1: Budget (placeholders - Aslam to fill the yellow cells)
A2: Annual = one-time + 12 x monthly. Org placeholders: Annual operating budget [$], Amount raised last year [$], Number of donors [#], 12-month goal [$].
A4: Annual operating budget [$] | D4: Amount raised last year [$]
A5: Number of donors [#] | D5: 12-month goal [$]
A7: A. Maa's Place + Blooming Star Village | B7: MP one-time | C7: MP monthly | D7: MP annual | E7: BSV one-time | F7: BSV monthly | G7: BSV annual | H7: Notes
A8: Lease deposit / rent | D8: =N(B8)+12*N(C8) | G8: =N(E8)+12*N(F8)
A9: Build-out, accessibility, safety | D9: =N(B9)+12*N(C9) | G9: =N(E9)+12*N(F9) | H9: Ramps, grab bars, sensory room
A10: Furniture, chairs, tables | D10: =N(B10)+12*N(C10) | G10: =N(E10)+12*N(F10)
A11: Kitchen / snack and chai equipment | D11: =N(B11)+12*N(C11) | G11: =N(E11)+12*N(F11)
A12: Activity and sensory supplies | D12: =N(B12)+12*N(C12) | G12: =N(E12)+12*N(F12)
A13: Snacks, chai, fruit | D13: =N(B13)+12*N(C13) | G13: =N(E13)+12*N(F13)
A14: Utilities, internet, phone | D14: =N(B14)+12*N(C14) | G14: =N(E14)+12*N(F14)
A15: Insurance (GL, D&O, accident; abuse & molestation for BSV) | D15: =N(B15)+12*N(C15) | G15: =N(E15)+12*N(F15) | H15: Get 2 quotes
A16: Background checks, training, first aid/CPR | D16: =N(B16)+12*N(C16) | G16: =N(E16)+12*N(F16)
A17: Licensing / exemption costs (BSV) | D17: =N(B17)+12*N(C17) | G17: =N(E17)+12*N(F17) | H17: Check Texas HHS child-care rules
A18: Coordinator / specialist staff (if any) | D18: =N(B18)+12*N(C18) | G18: =N(E18)+12*N(F18) | H18: See 'no salaries' question
A19: Cleaning, maintenance | D19: =N(B19)+12*N(C19) | G19: =N(E19)+12*N(F19)
A20: Signage, printing | D20: =N(B20)+12*N(C20) | G20: =N(E20)+12*N(F20)
A21: Other | D21: =N(B21)+12*N(C21) | G21: =N(E21)+12*N(F21)
A22: Total | B22: =SUM(B8:B21) | C22: =SUM(C8:C21) | D22: =SUM(D8:D21) | E22: =SUM(E8:E21) | F22: =SUM(F8:F21) | G22: =SUM(G8:G21)
A24: B. Fundraising costs (12 months) | B24: Low | C24: High | D24: Actual | H24: Notes
A25: Little Green Light CRM ($45/mo) | B25: 540 | C25: 540 | H25: Verified price Oct 13, 2026
A26: Printing and postage | B26: 1500 | C26: 3000
A27: Community Dinner (offset by sponsors) | B27: 5000 | C27: 15000
A28: Maa's Place opening event | B28: 500 | C28: 2000
A29: Sponsor kit, banners, signs | B29: 300 | C29: 800
A30: North Texas Giving Day | B30: 0 | C30: 300 | H30: CFT covers card fees
A31: Stripe fees | H31: 2.2% + 30c if nonprofit rate approved
A32: Total fundraising costs | B32: =SUM(B25:B31) | C32: =SUM(C25:C31) | D32: =SUM(D25:D31)
A34: C. Revenue estimates by source (12 months) | B34: Low | C34: High | D34: Midpoint | E34: Goal (set) | F34: Actual
A35: Monthly giving circle (Maa's Circle) | B35: 8000 | C35: 30000 | D35: =(B35+C35)/2 | H35: Cost: ~$0 (Stripe fees) · Owner: Aslam / Assistant
A36: Giving Tuesday + year-end appeal | B36: 8000 | C36: 25000 | D36: =(B36+C36)/2 | H36: Cost: $500-$1,500 print/postage · Owner: Aslam / Assistant
A37: Maa's Place opening campaign | B37: 15000 | C37: 50000 | D37: =(B37+C37)/2 | H37: Cost: $500-$2,000 event · Owner: Aslam / Staff
A38: Ramadan 'Share a Meal' with faith partners | B38: 10000 | C38: 40000 | D38: =(B38+C38)/2 | H38: Cost: $200-$800 · Owner: Aslam
A39: Diwali + Thanksgiving 'Share a Plate' | B39: 3000 | C39: 12000 | D39: =(B39+C39)/2 | H39: Cost: $200-$500 · Owner: Aslam / Volunteer
A40: Maa's Day (Mother's Day tribute) campaign | B40: 5000 | C40: 20000 | D40: =(B40+C40)/2 | H40: Cost: $300-$800 · Owner: Assistant / Aslam
A41: Annual Community Dinner (net) | B41: 15000 | C41: 45000 | D41: =(B41+C41)/2 | H41: Cost: $5,000-$15,000 · Owner: Aslam / Volunteer lead
A42: North Texas Giving Day 2027 | B42: 5000 | C42: 20000 | D42: =(B42+C42)/2 | H42: Cost: $0-$300 · Owner: Assistant / Aslam
A43: Business sponsors (local) | B43: 10000 | C43: 40000 | D43: =(B43+C43)/2 | H43: Cost: $300 sponsor kit · Owner: Aslam
A44: Corporate/retail grants | B44: 2000 | C44: 20000 | D44: =(B44+C44)/2 | H44: Cost: Staff time · Owner: Assistant / Aslam
...

Sheet Metrics
A1: Key Metrics (enter yellow cells monthly; grey rows calculate)
A2: Targets from the plan. Update by the 10th of each month.
A5: Metric | B5: Target | C5: Nov 2026 | D5: Dec 2026 | E5: Jan 2027 | F5: Feb 2027 | G5: Mar 2027 | H5: Apr 2027 | I5: May 2027 | J5: Jun 2027 | K5: Jul 2027 | L5: Aug 2027 | M5: Sep 2027 | N5: Oct 2027 | O5: 12-mo total
A6: Total raised ($) | O6: =SUM(C6:N6)
A7: Number of gifts | O7: =SUM(C7:N7)
A8: Unique donors | O8: =MAX(C8:N8)
A9: New donors | O9: =SUM(C9:N9)
A10: Active monthly donors (month end) | B10: 100 | O10: =IFERROR(LOOKUP(2,1/(C10:N10<>""),C10:N10),"")
A11: Monthly recurring revenue ($) | B11: 3000 | O11: =IFERROR(LOOKUP(2,1/(C11:N11<>""),C11:N11),"")
A12: Fundraising costs ($) | O12: =SUM(C12:N12)
A13: Gifts thanked within 48 hrs | O13: =SUM(C13:N13)
A14: Lapsed donors reactivated | O14: =SUM(C14:N14)
A15: Grants submitted | B15: 10 | O15: =SUM(C15:N15)
A16: Grants won | B16: 4 | O16: =SUM(C16:N16)
A17: Meals served | O17: =SUM(C17:N17)
A18: Meal costs ($) | O18: =SUM(C18:N18)
A19: Average gift ($) | C19: =IFERROR(C6/C7,"") | D19: =IFERROR(D6/D7,"") | E19: =IFERROR(E6/E7,"") | F19: =IFERROR(F6/F7,"") | G19: =IFERROR(G6/G7,"") | H19: =IFERROR(H6/H7,"") | I19: =IFERROR(I6/I7,"") | J19: =IFERROR(J6/J7,"") | ... O19: =IFERROR(O6/O7,"")
A20: Cost per dollar raised ($) | B20: 0.2 | C20: =IFERROR(C12/C6,"") | D20: =IFERROR(D12/D6,"") | E20: =IFERROR(E12/E6,"") | F20: =IFERROR(F12/F6,"") | G20: =IFERROR(G12/G6,"") | H20: =IFERROR(H12/H6,"") | I20: =IFERROR(I12/I6,"") | J20: =IFERROR(J12/J6,"") | ... O20: =IFERROR(O12/O6,"")
A21: 48-hour thank-you rate | B21: 0.95 | C21: =IFERROR(C13/C7,"") | D21: =IFERROR(D13/D7,"") | E21: =IFERROR(E13/E7,"") | F21: =IFERROR(F13/F7,"") | G21: =IFERROR(G13/G7,"") | H21: =IFERROR(H13/H7,"") | I21: =IFERROR(I13/I7,"") | J21: =IFERROR(J13/J7,"") | ... O21: =IFERROR(O13/O7,"")
A22: Grant win rate | B22: 0.35 | C22: =IFERROR(C16/C15,"") | D22: =IFERROR(D16/D15,"") | E22: =IFERROR(E16/E15,"") | F22: =IFERROR(F16/F15,"") | G22: =IFERROR(G16/G15,"") | H22: =IFERROR(H16/H15,"") | I22: =IFERROR(I16/I15,"") | J22: =IFERROR(J16/J15,"") | ... O22: =IFERROR(O16/O15,"")
A23: Cost per meal ($) | B23: 5 | C23: =IFERROR(C18/C17,"") | D23: =IFERROR(D18/D17,"") | E23: =IFERROR(E18/E17,"") | F23: =IFERROR(F18/F17,"") | G23: =IFERROR(G18/G17,"") | H23: =IFERROR(H18/H17,"") | I23: =IFERROR(I18/I17,"") | J23: =IFERROR(J18/J17,"") | ... O23: =IFERROR(O18/O17,"")
A26: Yearly retention
A27: Donors who gave last year (Nov 2025 - Oct 2026)
A28: Of those, donors who gave again this year
A29: First-time donors (12 months)
A30: Of those, gave a second gift
A31: Donor retention (target 50%+) | B31: =IFERROR(B28/B27,"")
A32: New-donor retention (target 35%+) | B32: =IFERROR(B30/B29,"")
